Workbook
Name Accompte: Paramètre!$D$36
Name action_fin: 'BASE CALCULS '!$J$4:$K$4
Name Ancrage: Cotation!$AO$13
Name Ancrage_tot: Cotation!$AO$15
Name arrayDeviseCode: Traduction!$H$5:$I$13
Name clientAdresse1: Paramètre!$D$8
Name clientAdresse2: Paramètre!$D$9
Name clientCP: Paramètre!$D$13
Name clientNom: Paramètre!$D$7
Name clientPays: Paramètre!$D$12
Name clientRegion: Paramètre!$D$11
Name clientVille: Paramètre!$D$10
Name codeDevise: Paramètre!$D$66
Name Complexite: Paramètre!$D$59
Name ConditionPaiement: Paramètre!$D$43
Name ConditionPaiementInd: Paramètre!$D$42
Name ConditionPaiementSaisie: Paramètre!$D$44
Name contactCel: Paramètre!$D$17
Name contactFax: Paramètre!$D$18
Name contactMail: Paramètre!$D$19
Name contactNom: Paramètre!$D$15
Name contactPrenom: Paramètre!$D$14
Name contactTel: Paramètre!$D$16
Name cotationEmetteur: Paramètre!$D$22
Name cotationEmission: Paramètre!$D$24
Name cotationEmissionAn: Paramètre!$E$24
Name cotationEmissionJour: Paramètre!$H$24
Name cotationEmissionMois: Paramètre!$G$24
Name cotationNom: Paramètre!$D$20
Name cotationNumero: Paramètre!$D$21
Name cotationValideur: Paramètre!$D$23
Name Couleur: 'Modele couleur'!$G$2
Name cout_achat_pierre: Cotation!$AE$9
Name CratePU: Paramètre!$D$37
Name debutCotation: Cotation!$A$13
Name debutTableau: 'Modele couleur'!$E$8
Name DelaiEscompte: Paramètre!$D$34
Name delaiNbr: Paramètre!$D$31
Name devideERP: Paramètre!$D$65
Name devideERPLibelle: Paramètre!$E$65
Name Devise.Client.Code: Paramètre!$D$65
Name Devise.Client.Libelle: Paramètre!$E$65
Name Devise.Libelle.en: Traduction!$E$5:$E$9
Name Devise.Libelle.fr: Traduction!$F$5:$F$9
Name deviseFacture: Cotation!$K$21
Name diam_trou: 'BASE CALCULS '!$J$9:$Y$9
Name dim_chan: 'BASE CALCULS '!$J$3:$AB$3
Name DureValidite: Paramètre!$D$32
Name encoche_: 'BASE CALCULS '!$J$15:$R$15
Name encoche_largeur: 'BASE CALCULS '!$J$13:$Y$13
Name Escompte: Paramètre!$D$35
Name Export: Paramètre!$D$62
Name Feuille: Paramètre!$D$61
Name fin_cote_man: 'BASE CALCULS '!$J$7:$U$7
Name fin_des_auto: 'BASE CALCULS '!$J$5:$S$5
Name fin_des_man: 'BASE CALCULS '!$J$6:$S$6
Name Finition: Cotation!$AN$13
Name Finition_tot: Cotation!$AN$15
Name HautStandardReference: Cotation!$AX$12
Name Imprimante: Paramètre!$D$63

Sheet Paramètre
B2: Catégorie | C2: Détail | D2: Valeur | E2: Calcul | G2: Devise connus par symbole
B3: Information technique | C3: Nom du fichier | D3: Valeur lors de la génération | G3: Symbole | H3: Libellé
C4: Nom fichier parametre | D4: P:\Travail\DRC\Conception\vb\data\domino\html\erp\drc\echange\60E012AF762CA7E8C12575DB00267D16.xml | G4: CAD | H4: =VLOOKUP("Canadian Dollar",tableauTraductions,LangueColonne) -> Canadian Dollar
C5: Version de la macro | D5: 4 | G5: CNY | H5: =VLOOKUP("Renminbi",tableauTraductions,LangueColonne) -> Renminbi
C6: Nom fichier cible | G6: EUR | H6: =VLOOKUP("Euro",tableauTraductions,LangueColonne) -> Euro
B7: Client | C7: Nom | D7: A6 | G7: GBP | H7: =VLOOKUP("Pound",tableauTraductions,LangueColonne) -> Pound
C8: Adresse 1 | G8: USD | H8: =VLOOKUP("U.S. Dollar",tableauTraductions,LangueColonne) -> U.S. Dollar
C9: Adresse 2
C10: Ville | G10: Condition de paiement et traduction équivalente (Le code est donné par le système) | K10: Unité de vente
C11: Region | D11: CA-QC | G11: Code | H11: Anglais | I11: Francais | K11: Anglais | L11: Français
C12: Pays | D12: CA | G12: 1 | H12: Payment upon confirmation of order | I12: Paiement à la commande | K12: / ea | L12: / piece
C13: Code postal | D13: 1041 | G13: 2 | H13: =CONCATENATE(TEXT(Accompte,"0%")," deposit on confirmation of order, balance before delivery") -> 5% deposit on confirmation of order, balance before delivery | I13: =CONCATENATE(TEXT(Accompte,"0%")," à la commande, le solde avant expédition") -> 5% à la commande, le solde avant expédition | K13: / LF | L13: / plin
B14: Contact | C14: Prenom | D14: Henry | G14: 3 | H14: =CONCATENATE(TEXT(Accompte,"0%")," deposit on confirmation of order, balance net ",Paiement," days after date of invoice") -> 5% deposit on confirmation of order, balance net 30 days after date of invoice | I14: =CONCATENATE(TEXT(Accompte,"0%")," à la commande le solde ",Paiement," jours net après date de facturation") -> 5% à la commande le solde 30 jours net après date de facturation | K14: / SF | L14: / pi2
C15: Nom | D15: Matisse | G15: 4 | H15: =CONCATENATE("net ",Paiement," days and ",TEXT(Escompte,"0%")," discount if payment by WIRE TRANSFER is received before ",DelaiEscompte," days from date of invoice") -> net 30 days and 5% discount if payment by WIRE TRANSFER is received before 30 days from date of invoice | I15: =CONCATENATE("net ",Paiement," jours avec ",TEXT(Escompte,"0%")," d’escompte si paiement reçu par VIREMENT BANCAIRE chez DRC avant ",DelaiEscompte," jours net date de facturation") -> net 30 jours avec 5% d’escompte si paiement reçu par VIREMENT BANCAIRE chez DRC avant 30 jours net date de facturation | K15: / CF | L15: / pi3
C16: Tel | D16: +1 (418) | G16: 5 | H16: =CONCATENATE("net ",Paiement," days of date of invoice") -> net 30 days of date of invoice | I16: =CONCATENATE("net ",Paiement," jours après date de facturation") -> net 30 jours après date de facturation | K16: / linM | L16: / Mlin
C17: Cel | D17: +1 (418) | G17: 6 | H17: Terms to be confirmed | I17: A déterminer | K17: / m2 | L17: / m2
C18: Fax | D18: +1 (418) | K18: / m3 | L18: / m3
C19: Mail | G19: 8 | H19: =CONCATENATE(TEXT(Accompte,"0%")," deposit on confirmation of order and ",TEXT(Escompte,"0%")," discount on balance if payment received before ",DelaiEscompte," days from date of invoice") -> 5% deposit on confirmation of order and 5% discount on balance if payment received before 30 days from date of invoice | I19: =CONCATENATE(TEXT(Accompte,"0%")," à la commande et ",TEXT(Escompte,"0%")," de remise sur le solde si paiement reçu sous ",DelaiEscompte," jours") -> 5% à la commande et 5% de remise sur le solde si paiement reçu sous 30 jours
B20: Cotation | C20: Projet | D20: Projet Morrin Centre
C21: Numero | D21: DRC09-0004-C1R0 | E21: =MID(cotationNumero,8,3) -> 004
C22: Emetteur | D22: CN=Stanislas Tardy/O=SOPRA
C23: Valideur
C24: Emission | D24: =DATE(cotationEmissionAn,cotationEmissionMois,cotationEmissionJour) -> 40544 | E24: 2011 | G24: 1 | H24: 1
B25: Représentant | C25: Nom | D25: Inconnu
C26: Prénom | D26: Inconnu
C27: Tel | D27: Inconnu
C28: Cel | D28: Inconnu
C29: Fax | D29: Inconnu
C30: Mail | D30: Inconnu
B31: Divers | C31: Nombre de semaine | D31: 0
C32: Durée de validité | D32: 30
C33: Délai de paiement | D33: 30
C34: Délai escompte | D34: =Paiement -> 30
C35: Taux d'escompte | D35: 0.05
C36: Accompte | D36: 0.05
C37: Cout de la pallette | D37: 12
C38: Taux de change | D38: 1.05
C39: Langue | D39: en | E39: =IF(UPPER(Langue)="FR",2,1) -> 1
C40: Systemen de mesure | E40: Impérial
C41: Systeme de mesure | E41: =Mesure -> Impérial
...

Sheet Traduction
B2: =VLOOKUP("CAUTION: For the system to work the table must be sorted on the column in French",tableauTraductions,LangueColonne) -> CAUTION: For the system to work the table must be sorted on the column in French
E3: Traduction des libellé des devises : Attention chaque langue doit être trié individuellement | H3: ALL Traduction
B4: Anglais | C4: Français | E4: Anglais | F4: Français | H4: Libelle | I4: Symbole
B5: cell. : | C5: cell. : | E5: Canadian Dollar | F5: Dollar canadien | H5: Canadian Dollar | I5: CAD
B6: week(s) after reception of approved shop tickets, purchase order according to latest quotation, payment of deposit if applicable and approved samples | C6: semaine(s) après réception des dessins d'atelier approuvés, du bon de commande correspondant à la dernière soumission, du règlement de l'avance si requis et de l'approbation des échantillons | E6: Euro | F6: Dollar US | H6: Dollar canadien | I6: CAD
B7: Adress : | C7: Adresse : | E7: Pound | F7: Euro | H7: Dollar US | I7: USD
B8: Average weight per crate is: | C8: Poids moyen par palette est: | E8: Renminbi | F8: Livre sterling | H8: Euro | I8: EUR
B9: Canadian Dollar | C9: Dollar canadien | E9: U.S. Dollar | F9: Yuan renminbi | H9: Livre sterling | I9: GBP
B10: CAUTION: For the system to work the table must be sorted on the column in French | C10: ATTENTION : Pour que le système marche le tableau doit être trié sur la colonne en français | H10: Pound | I10: GBP
B11: Comment(s) : Shop tickets and installation plan are to be provided by customer; All finished edge is considered with a minimum chamfer 1/8'' unless if another size is requested; excepted for rockface finish | C11: Note(s) : Dessins et plan d'installation fournis par le client; Toutes arêtes finies sont considérées avec un chanfrein minimum 1/8'' sauf si indication contraire, excepté pour le rockface | H11: Renminbi | I11: CNY
B12: Confirmed by : | C12: Approuvé par : | H12: U.S. Dollar | I12: USD
B13: Currency : | C13: Devise : | H13: Yuan renminbi | I13: CNY
B14: Customer : | C14: Client :
B15: days | C15: jours | E15: week(s) after reception of approved shop tickets and purchase order according to latest quotation
B16: Estimated start of delivery: | C16: Date estimée début de livraison:
B17: Euro | C17: Euro
B18: In Stock | C18: En stock
B19: Incoterm : | C19: Incoterm :
B20: LENGTH | C20: LONG
B21: Payment : | C21: Paiement :
B22: Please verify the data and dimensions; it is the customer's responsibility to confirm that the descriptions mentioned in this quote all match the project requirements | C22: Veuillez vérifier les données et les dimensions; il est de la responsabilité du client de confirmer que les descriptions mentionnées dans ce devis correspondent toutes aux exigences du projet
B23: Pound | C23: Livre sterling
B24: Price confirmation | C24: Confirmation de prix
B25: QTY | C25: QTÉ
B26: Ready for delivery : | C26: Délais :
B27: Renminbi | C27: Yuan renminbi
... B41: WIDTH DEEP | C41: LARG PROF

Sheet Cotation
U1: =cotationNumero -> DRC09-0004-C1R0
AB2: 11.9999 | AC2: FORMAT SI MESURES MÉTRIQUES | AF2: VU AVEC: | AI2: DATE:
N3: =SUBSTITUTE(SUBSTITUTE(cotationNom,"_"," "),"&amp;","&") -> Projet Morrin Centre | U3: =VLOOKUP("Price confirmation",tableauTraductions,LangueColonne) -> Price confirmation | AB3: 1000 | AC3: 400 | AD3: 400 | AE3: 300
G4: =delaiNbr -> 0 | AB4: RATIO CAD | AC4: RATIO US
U5: =cotationEmission -> 40544 | AB5: =+AB7/AE8 -> 5.0682398 | AC5: =+AB7/AE5 -> 6.5887117 | AE5: =+AE8/1.3 -> 62.60708 | AG5: Nombre de ligne | AH5: =ROW(Total)-ROW(Ligne1)-1 -> 1 | BA5: TRADUCTION TYPE D'ITEM | BD5: TRADUCTION FINITION STANDARD
I6: =VLOOKUP("Customer :",tableauTraductions,LangueColonne) -> Customer : | J6: =clientNom -> A6 | AB6: $ TOTAL SANS TRANSPORT | AD6: Taux de change | AE6: 1 | AF6: PRIX / EMBALLAGE | AG6: PRIX THÉORIQUE VENDANT CAD | AI6: PRIX THÉORIQUE VENDANT USD | AK6: VALEUR PALETTE LIVRÉ | BA6: FR | BB6: EN | BD6: FR | BE6: EN
I7: =VLOOKUP("Adress :",tableauTraductions,LangueColonne) -> Adress : | J7: =IF(clientAdresse1="","",clientAdresse1) | AB7: =INDIRECT(CONCATENATE("'",Couleur,"'!CI",ROW(M13)-6)) -> 412.5 | AD7: Pi3 Pierre Brut | AE7: =+volumeTotal*1.4 -> 13.066667 | AF7: 25 | AG7: =+(AE8*3)/(1-Escompte) -> 257.01854 | AI7: =+AG7/1.3 -> 197.70657 | AK7: =INDIRECT(CONCATENATE("'",Couleur,"'!CH",ROW(U13)-6)) -> 3162.5 | BA7: Marche | BB7: Step | BD7: Dessus flammé, rock devant 1 long et 2 courts, balance sciée | BE7: Thermal top, rock 3 sides, saw balance
J8: =CONCATENATE(clientVille,", ",clientRegion," ",clientCP) -> , CA-QC 1041 | AB8: SANS TRANSPORT - COMM. REPR. | AD8: Achat Pierre Brut | AE8: =+cout_achat_pierre*(AE7/35.32) -> 81.389203 | AF8: =ROUNDUP(Z25/Z26,0) -> 1 | AG8: =+(AB7-AE8)/volumeTotal -> 35.476157 | AI8: =+(AB7-AE5)/volumeTotal -> 37.488527 | AJ8: COÛT TRANSFORMATION | BA8: Perron | BB8: Landing | BD8: Dessus flammé, rock devant 1 long et 2 courts, balance sciée | BE8: Thermal top, rock 3 sides, saw balance
I9: Attn. : | J9: =CONCATENATE(contactPrenom," ",contactNom," tél. : ",contactTel," cell. : ",contactCel," Fax. : ",contactFax) -> Henry Matisse tél. : +1 (418) cell. : +1 (418) Fax. : +1 (418) | AB9: =+AB7*0.9 -> 371.25 | AD9: Cout Pierre/M3 | AE9: ='Modele couleur'!H2 -> 220 | AF9: =+AF8*AF7 -> 25 | AG9: PRIX /PIECE | BA9: Dessus de marche | BB9: Tread | BD9: Dessus flammé, rock devant 1 long et 2 courts, balance sciée | BE9: Thermal top, rock 3 sides, saw balance
AD10: % du total de la soumission | AE10: =+AE8/TotalInterne -> 0.18603247 | AF10: =IF(Incoterm="Ex Works",(Total-AB7),Total-AK7) -> 25 | BA10: Cap | BB10: Cap | BD10: Dessus flammé, 4 côtés rockface, dessous scié | BE10: Thermal top, rock 4 sides, sawn bottom
B11: code erp | C11: type pdt | D11: Densité | E11: std ou semi std ? | F11: NO T-1000 | G11: % majoration Semi-STD | H11: NO | I11: REF | J11: TAG | K11: GRANITE | L11: =VLOOKUP("QTY",tableauTraductions,LangueColonne) -> QTY | M11: ITEM | N11: =VLOOKUP("LENGTH",tableauTraductions,LangueColonne) -> LENGTH | O11: =VLOOKUP("WIDTH DEEP",tableauTraductions,LangueColonne) -> WIDTH DEEP | P11: =VLOOKUP("THICK HEIGHT",tableauTraductions,LangueColonne) -> THICK HEIGHT | Q11: DESCRIPTION | R11: =VLOOKUP("TOTAL LENGTH NET",tableauTraductions,LangueColonne) -> TOTAL LENGTH NET | S11: =VLOOKUP("TOTAL AREA NET",tableauTraductions,LangueColonne) -> TOTAL AREA NET | T11: =VLOOKUP("TOT. VOLUME NET",tableauTraductions,LangueColonne) -> TOT. VOLUME NET | U11: =VLOOKUP("TOT. WEIGHT",tableauTraductions,LangueColonne) -> TOT. WEIGHT | V11: =CONCATENATE(VLOOKUP("UNIT PRICE.",tableauTraductions,LangueColonne)," ",IF(UC="","CDN",UC),"$") -> UNIT PRICE. CAD$ | W11: =CONCATENATE(VLOOKUP("UNIT PRICE.",tableauTraductions,LangueColonne)," ",codeDevise,"$") -> UNIT PRICE. USD$ | X11: =VLOOKUP("UNIT",tableauTraductions,LangueColonne) -> UNIT | Y11: TOTAL CDN$ | Z11: =CONCATENATE("TOTAL ",codeDevise,"$") -> TOTAL USD$ | AC11: LF/PIECE | AD11: SF/PIECE | AF11: =+AF10-AF9 -> 0 | AG11: LF | AH11: SF | AI11: CALCUL $ / VOLUME MOYEN | AJ11: ='Modele couleur'!CL6 -> Valeur de pierre | AK11: ='Modele couleur'!CM6 -> Sciage primaire | AL11: ='Modele couleur'!CN6 -> Sciage secondaire | AM11: ='Modele couleur'!CO6 -> Profilage | AN11: ='Modele couleur'!CP6 -> Finition | AO11: ='Modele couleur'!CQ6 -> Ancrages | AP11: ='Modele couleur'!CR6 -> TEMPS UNITAIRE | AQ11: ='Modele couleur'!CS6 -> TEMPS TOTAL | BA11: Pavé | BB11: Paver | BD11: Dessus flammé, balance sciée | BE11: Thermal top, saw balance
N12: X | O12: Y | P12: Z | R12: X | S12: XY | T12: XYZ | AC12: Plin/pièce | AD12: Pi2/pièce | AE12: Cout unitaire | AF12: EMBALLAGE | AG12: $ PIÈCE (PLIN) | AH12: $ PIÈCE (PI2) | AJ12: ='Modele couleur'!CL7 -> V | AK12: ='Modele couleur'!CM7 -> P | AL12: ='Modele couleur'!CN7 -> S | AM12: ='Modele couleur'!CO7 -> G | AN12: ='Modele couleur'!CP7 -> F | AO12: ='Modele couleur'!CQ7 -> A | AP12: ='Modele couleur'!CR7 -> TU | AQ12: ='Modele couleur'!CS7 -> TT | BA12: Limon | BB12: Filler | BD12: Devant rockface, dos scié / guillotiné, balance sciée | BE12: Rockface front, sawn / splitted back, saw balance
E13: =OR(C13="Standard",C13="Semi-standard") -> FALSE | G13: =TxSemi -> 0 | H13: L1 | J13: =CONCATENATE(TAG,"-",ROW(G13)-ROW(Ligne1)+1) -> 004-1 | K13: Modele couleur | L13: 1 | M13: step | N13: 96 | O13: 24 | P13: 7 | Q13: A renseigner | R13: =IF(Mesure="Impérial",N13/12*L13,N13/12*L13/25.4) -> 8 | S13: =IF(Mesure="Impérial",N13*O13/144*L13,N13*O13/144*L13/25.4/25.4) -> 16 | T13: =IF(Mesure="Impérial",N13*O13*P13/1728*L13,N13*O13*P13/1728*L13/25.4/25.4/25.4) -> 9.3333333 | U13: =IF(OR(I13="CALD-1",I13="CALD-2",I13="CALD-3",I13="CALD-4",I13="SAPD-1",I13="SAPD-2",I13="SAPD-3",I13="GVD-1",I13="GVD-2",I13="GVD-3",I13="GVD-4",I13="GVD-5"),A13,T13*IF(E13,D13,PoidsUnitaire)) -> 1680 | V13: =ROUND(IF(AND(Incoterm="Ex Works",LOADVille="RIVIÈRE-À-PIERRE"),IF(E13,IF(C13="Semi-standard",INDIRECT(CONCATENATE("'",Couleur,"'!bw",ROW(M13)-5))*(1+G13),INDIRECT(CONCATENATE("'",Couleur,"'!bw",ROW(M13)-5))),INDIRECT(CONCATENATE("'",IF(E13,Couleur,K13),"'!bw",ROW(M13)-5))),IF(E13,IF(C13="Semi-standard",INDIRECT(CONCATENATE("'",Couleur,"'!bw",ROW(M13)-5))*(1+G13),INDIRECT(CONCATENATE("'",Couleur,"'!bw",ROW(M13)-5))),INDIRECT(CONCATENATE("'",Couleur,"'!ca",ROW(M13)-5))))+AF13,1) -> 437.5 | W13: =ROUND(IF(OR(codeDevise=UC,F13),V13,ROUND(V13/TauxChange,1)),1) -> 437.5 | X13: / ea | Y13: =L13*V13 -> 437.5 | Z13: =W13*L13 -> 437.5 | AC13: =R13/L13 -> 8 | AD13: =S13/L13 -> 16 | AF13: =ROUNDUP(U13/3000,0)*$AF$7/L13 -> 25 | AG13: =AC13*AE13 -> 0 | AH13: =AD13*AE13 -> 0 | AI13: =+Z13/T13 -> 46.875 | AJ13: =INDIRECT(CONCATENATE("'",Couleur,"'!CL",ROW(M13)-5)) -> 58.168083 | AK13: =INDIRECT(CONCATENATE("'",Couleur,"'!CM",ROW(M13)-5)) -> 78.115556 | AL13: =INDIRECT(CONCATENATE("'",Couleur,"'!CN",ROW(M13)-5)) -> 43.75 | AM13: =INDIRECT(CONCATENATE("'",Couleur,"'!CO",ROW(M13)-5)) -> 0 | AN13: =INDIRECT(CONCATENATE("'",Couleur,"'!CP",ROW(M13)-5)) -> 0 | AO13: =INDIRECT(CONCATENATE("'",Couleur,"'!CQ",ROW(M13)-5)) -> 0 | AP13: =INDIRECT(CONCATENATE("'",Couleur,"'!CR",ROW(M13)-5)) -> 2.0310926 | AQ13: =INDIRECT(CONCATENATE("'",Couleur,"'!CS",ROW(M13)-5)) -> 2.0310926 | BA13: Lampadaire | BB13: Lamp post | BD13: 2 longs opposés flammés, 2 autres longs opposés rockace, bouts scié; trou centré sur la longueur | BE13: Thermal opposite 2 long sides; 2 other opposite long sides rocked; ends splitted; with hole
BA14: Poteau | BB14: Post | BD14: 2 longs opposés flammés, 2 autres longs opposés rockace, boutsguillotinés | BE14: Thermal opposite 2 long sides; 2 other opposite long sides rocked; ends splitted
H15: TOTAL | L15: =SUBTOTAL(9,L13:L14) -> 1 | R15: =SUBTOTAL(9,R13:R14) -> 8 | S15: =SUBTOTAL(9,S13:S14) -> 16 | T15: =SUBTOTAL(9,T13:T14) -> 9.3333333 | U15: =SUBTOTAL(9,U13:U14) -> 1680 | Y15: =SUBTOTAL(9,Y13:Y14) -> 437.5 | Z15: =SUBTOTAL(9,Z13:Z14) -> 437.5 | AH15: Total | AI15: =AVERAGE(AI13:AI14) -> 46.875 | AJ15: =SUBTOTAL(9,AJ13:AJ14) -> 58.168083 | AK15: =SUBTOTAL(9,AK13:AK14) -> 78.115556 | AL15: =SUBTOTAL(9,AL13:AL14) -> 43.75 | AM15: =SUBTOTAL(9,AM13:AM14) -> 0 | AN15: =SUBTOTAL(9,AN13:AN14) -> 0 | AO15: =SUBTOTAL(9,AO13:AO14) -> 0 | AP15: =AVERAGE(AP13:AP14) -> 2.0310926 | AQ15: =SUBTOTAL(9,AQ13:AQ14) -> 2.0310926 | BA15: Pas japonais | BB15: Flagstone | BD15: Dessus flammé, forme irrégulière, côtés bruts / naturels | BE15: Thermal top, irregular shape, rough / natural sides
W16: SHOP TICKETS | Z16: =+Total*0.05 -> 21.875
W17: GRAND TOTAL | Z17: =+Total+Z16 -> 459.375
BA18: Perron radial | BB18: Radius landing | BD18: Dessus flammé, rock rayon au devant, balance sciée | BE18: Thermal top, rocked radius edge at front, saw balance
H19: =VLOOKUP("Comment(s) : Shop tickets and installation plan are to be provided by customer; All finished edge is considered with a minimum chamfer 1/8'' unless if another size is requested; excepted for rockface finish",tableauTraductions,LangueColonne) -> Comment(s) : Shop tickets and installation plan are to be provided by customer; All finished edge is considered with a minimum chamfer 1/8'' unless if another size is requested; excepted for rockface finish
H21: =VLOOKUP("Currency :",tableauTraductions,LangueColonne) -> Currency : | K21: =devideERPLibelle -> U.S. Dollar
H22: =VLOOKUP("Estimated starting delivery date:",tableauTraductions,LangueColonne) -> Estimated start of delivery: | K22: =IF(delaiNbr=0,VLOOKUP("In Stock",tableauTraductions,LangueColonne),CONCATENATE(delaiNbr," - ",delaiNbr+1,VLOOKUP(" week(s) after reception of approved shop tickets, purchase order according to latest quotation, payment of deposit if applicable and approved samples",tableauTraductions,LangueColonne))) -> In Stock
H23: =VLOOKUP("Payment :",tableauTraductions,LangueColonne) -> Payment : | K23: =IF(ConditionPaiementInd=7,ConditionPaiementSaisie,VLOOKUP(ConditionPaiementInd,lstConditionPaiement,LangueColonne+1,FALSE)) -> 0
H24: =VLOOKUP("Validity :",tableauTraductions,LangueColonne) -> Validity : | K24: =CONCATENATE(DureValidite," ",VLOOKUP("days",tableauTraductions,LangueColonne)) -> 30 days
H25: =VLOOKUP("Incoterm :",tableauTraductions,LangueColonne) -> Incoterm : | K25: =IF(IncotermInd<>3,CONCATENATE(Incoterm," : ",LOADVille," - ",LOADRegiondsp),IncotermS) -> Ex Works : RIVIÈRE-À-PIERRE - Québec | Q25: =VLOOKUP("Total estimated weight of project: ",tableauTraductions,LangueColonne) -> Total estimated weight of project: | Z25: =PoidTotal -> 1680
Q26: =VLOOKUP("Average weight per crate is: ",tableauTraductions,LangueColonne) -> Average weight per crate is: | Z26: 3000
H27: =CONCATENATE(VLOOKUP("Sales representative : ",tableauTraductions,LangueColonne),representantPrenom," ",representantNom,VLOOKUP(" cell. : ",tableauTraductions,LangueColonne),representantCel) -> Sales representative : Inconnu Inconnu cell. : Inconnu
H29: =VLOOKUP("This quote is valid if the order includes all the details mentioned above and if the stone is available at the date of purchase. ALL PRODUCTION DONE WILL BE IMMEDIATELY INVOICED.",tableauTraductions,LangueColonne) -> This quote is valid if the order includes all the details mentioned above and if the stone is available at the date of purchase. ALL PRODUCTION DONE WILL BE IMMEDIATELY INVOICED.
H30: =VLOOKUP("Please verify the data and dimensions; it is the customer's responsibility to confirm that the descriptions mentioned in this quote all match the project requirements",tableauTraductions,LangueColonne) -> Please verify the data and dimensions; it is the customer's responsibility to confirm that the descriptions mentioned in this quote all match the project requirements
H31: =VLOOKUP("To order: sign below & fax or email us ",tableauTraductions,LangueColonne) -> To order: sign below & fax or email us
H32: P.O. # : | Q32: =VLOOKUP("Confirmed by :",tableauTraductions,LangueColonne) -> Confirmed by :
H33: =IF(LangueColonne=1,CONCATENATE("Fax : +1 (418) 323-2123 Tél : +1 (418) 323-2455 Email : order@granitedrc.com 100$ will be charged for preparation of shipping documents and customs clearance of each delivery"," 50% of initial price per piece will be added in case of replacement on same project"),CONCATENATE("Fax: +1 (418) 323-2123 Tél: +1 (418) 323-2455 Courriel: commande@granitedrc.com"," Les prix indiqués sont hors taxes; 50% seront ajouté au prix initial de chaque pièce dans l'éventualité d'un remplacement")) -> Fax : +1 (418) 323-2123 Tél : +1 (418) 323-2455 Email : order@granitedrc.com 100$ will be charged for preparation of shipping documents and customs clearance of each delivery 50% of initial price per piece will be added in case of replacement on same project
H34: =CONCATENATE("Par / By:"," ",cotationEmetteur) -> Par / By: CN=Stanislas Tardy/O=SOPRA | Q34: =cotationValideur -> 0

Sheet Modele couleur
G1: Couleur | H1: Prix | I1: Unite | J1: perte | K1: Prix/pi3 | O1: qualite | BS1: N°colonne Prix | BY1: =Incoterm -> Ex Works | BZ1: 2500 | CB1: poids camion de base | CD1: 45000
G2: Modele couleur | H2: 220 | K2: =H2*(1+J2)/IF(I2="pi3",1,35.3) -> 6.2322946 | BY2: poids / voyage | BZ2: =+CD2/CD4 -> 1680 | CB2: Total poids | CD2: =PoidTotal -> 1680
G3: =CONCATENATE(G2," (",H2,"/",I2," ) +",TEXT(J2,"00%")," perte") -> Modele couleur (220/ ) +00% perte | H3: =CONCATENATE(Couleur," (",Prix,"/",Unite," ) +",TEXT(perte,"00%")," perte") -> Modele couleur (220/ ) +00% perte | BY3: poids pi3 | BZ3: 180 | CB3: Nb de camion | CD3: =+CD2/CD1 -> 0.037333333
BY4: nb. Pi3 / voyage | BZ4: =BZ2/BZ3 -> 9.3333333 | CB4: Nb camion necessaire | CD4: =INT(CD3+1) -> 1
I5: facteur selon épaiseur pr trait supp. + 30% perte | BW5: TOTAL SOUMISSION | BY5: $ / pi3 | BZ5: =BZ1/BZ4*1.1 -> 294.64286 | CC5: Total | CD5: Total | CE5: Total | CF5: DIFFÉRENCE COÛT TRANSPORT
H6: volume | I6: sciage primaire | J6: sciage secondaire | K6: sciage secondaire supplémentaire | L6: Usinage au Pi2 | M6: Usinage au Pi2 #2 | N6: Calcul temps machine | O6: Calcul temps #2 | P6: Trou 1 | Q6: Trou 2 | R6: Rockface | S6: Split | T6: Finition Dessus Auto | U6: Finition Dessus Manu | V6: Finition Coté Manu 1 | W6: ou ? fintion Manu 1 | X6: Finition Coté Manu 2 | Y6: ou ? fintion Manu 2 | Z6: Chanfrein | AA6: ou ? Chanfrein | AB6: Qté Slot | AC6: Longueur slot | AD6: qté Trou | AE6: diam trou | AF6: prof trou | AG6: Encoche | AH6: Largeur encoche | AI6: Prof encoche | AJ6: Libre 1 | AK6: Libre 2 | AL6: $ granite | AM6: sciage primaire | AN6: sciage secondaire | AO6: =+K6 -> sciage secondaire supplémentaire | AP6: =+L6 -> Usinage au Pi2 | AQ6: =+M6 -> Usinage au Pi2 #2 | AR6: =+N6 -> Calcul temps machine | AS6: =+O6 -> Calcul temps #2 | AT6: =+P6 -> Trou 1 | AU6: =+Q6 -> Trou 2 | AV6: =+R6 -> Rockface | ... BC6: =+Y6 -> ou ? fintion Manu 2 | BD6: Ajout petite taille | BE6: =+Z6 -> Chanfrein | BF6: =+AA6 -> ou ? Chanfrein | BG6: Slot | BH6: =+AC6 -> Longueur slot | BI6: Trou | BJ6: Qté trous | BK6: =AG6 -> Encoche | BL6: =AH6 -> Largeur encoche | BM6: =AJ6 -> Libre 1 | BN6: =AK6 -> Libre 2 | BO6: total | BP6: marge | BQ6: Prix vente avant com | BR6: Marge commercial | BS6: 30 jours + | BW6: =Total -> 437.5 | BZ6: surplus transport / piece | CA6: total transport | CB6: =+CD4*BZ1 -> 2500 | CC6: =SUM(CC8:CC300) -> 412.48 | CD6: =SUM(CD8:CD300) -> 3162.5 | CE6: =SUM(CE8:CE300) -> 2750.02 | CF6: =+CE6-CB6 -> 250.02 | CH6: TOTAL LIVRÉ | CI6: TOTAL EXWORKS | CL6: Valeur de pierre | CM6: Sciage primaire | CN6: Sciage secondaire | CO6: Profilage | CP6: Finition | CQ6: Ancrages | CR6: TEMPS UNITAIRE | CS6: TEMPS TOTAL | CU6: G | CV6: F | CW6: A | CY6: G | DC6: F | DG6: A
A7: Ligne | B7: Tag | C7: Qté | D7: Finition | E7: Lo | F7: La | G7: Ép | H7: pi3 | I7: pi2 | J7: pi2 | K7: pi2 | L7: pi2 | M7: pi2 | N7: hre | O7: hre | P7: qté | Q7: qté | R7: plin | S7: plin | T7: cal par pl | U7: cal par pl | V7: cal par pl | W7: cal par pl | X7: cal par pl | Y7: cal par pl | Z7: table_chan | AA7: cal par pl | AB7: nb_slot | AC7: en " | AD7: nombre | AE7: en " | AF7: en " | AG7: cal par pl | AH7: en " | AI7: en " | AJ7: Qté | AK7: Qté | AM7: 3.25 | AN7: ='BASE CALCULS '!F18 -> 3.75 | AO7: 10 | AP7: 20 | AQ7: 8 | AR7: 100 | AS7: 70 | AT7: 7.5 | AU7: 15 | AV7: 7 | AW7: 4 | AX7: fin_des_auto | AY7: fin_des_manu | AZ7: fin_cote_man | BA7: total longeur | BB7: fin_cote_man | BC7: total longeur | BD7: Volume | BE7: table_chan | BF7: total longeur | BG7: nb_slot | BH7: Qté | BI7: cout total | BJ7: Qté | BK7: table_enc | BL7: total longueur | BM7: 10 | BN7: 20 | BP7: 0.7 | BR7: 0.95 | BS7: 0.95 | BT7: Prix au pi3 | BU7: Prix au pi2 | BV7: Prix au plin | BW7: EX WORKS | BY7: pi3 / unité | BZ7: =BZ5 -> 294.64286 | CA7: FOB | CC7: total ligne | CD7: total ligne +T | CE7: diff | CF7: LF / Pièce | CG7: SF / Pièce | CH7: =SUM(CH8:CH300) -> 3162.5 | CI7: =SUM(CI8:CI300) -> 412.5 | CL7: V | CM7: P | CN7: S | CO7: G | CP7: F | CQ7: A | CR7: TU | CS7: TT | CU7: CALCULS TEMPS | CY7: Temps au Pi3 | CZ7: Temps au Pi2 | DA7: Temps au Plin | DC7: Temps au Pi3 | DD7: Temps au Pi2 | DE7: Temps au Plin | DG7: Temps au Pi3 | DH7: Temps au Pi2 | DI7: Temps au Plin
A8: =+Cotation!H13 -> L1 | B8: =+Cotation!J13 -> 004-1 | C8: =Cotation!L13 -> 1 | D8: =Cotation!Q13 -> A renseigner | E8: =IF(Mesure="Impérial",+Cotation!N13,+Cotation!N13/25.4) -> 96 | F8: =IF(Mesure="Impérial",+Cotation!O13,+Cotation!O13/25.4) -> 24 | G8: =IF(Mesure="Impérial",+Cotation!P13,+Cotation!P13/25.4) -> 7 | H8: =E8*F8*G8/1728 -> 9.3333333 | I8: =E8*F8/144*VLOOKUP(G8,tableepaisseur,2)*1.3 -> 24.035556 | J8: 2l2c | K8: 0 | L8: 0 | M8: 0 | N8: 0 | O8: 0 | P8: 0 | Q8: 0 | R8: 0 | S8: 0 | T8: aucune | U8: aucune | V8: aucune | W8: 2l2c | X8: aucune | Y8: 1l | Z8: aucun | AA8: 2l | AB8: aucune | AC8: 1 | AD8: aucun | AE8: 0.125 | AF8: 0.5 | AG8: aucune | AH8: 0.25 | AI8: 0.25 | AJ8: 0 | AK8: 0 | AL8: =H8*$K$2 -> 58.168083 | AM8: =I8*$AM$7 -> 78.115556 | AN8: =IF(J8="aucun",0,IF(J8="2l1c",(((E8*2)+F8)/12),IF(J8="1l1c",(E8+F8)/12,IF(J8="1l",(E8/12),IF(J8="1l2c",(E8+(F8*2))/12,IF(J8="2l",E8*2/12,IF(J8="2l2c",(E8*2+F8*2)/12,IF(J8="2c",F8*2/12,F8/12)))))))*VLOOKUP(F8,table_secondaire,3)*G8/12) -> 43.75 | AO8: =K8*$AO$7 -> 0 | AP8: =L8*$AP$7 -> 0 | AQ8: =M8*$AQ$7 -> 0 | AR8: =N8*$AR$7 -> 0 | AS8: =O8*$AS$7 -> 0 | AT8: =P8*$AT$7 -> 0 | AU8: =Q8*$AU$7 -> 0 | AV8: =+$AV$7*R8 -> 0 | AW8: =+$AW$7*S8 -> 0 | AX8: =IF(T8="aucune",0,INDEX(table_fd_auto,MATCH(F8,'BASE CALCULS '!$H$21:$H$120,1),MATCH(T8,'BASE CALCULS '!$J$20:$R$20,0))*E8/12) -> 0 | AY8: =IF(U8="aucune",0,INDEX(table_fd_manu,MATCH(F8,'BASE CALCULS '!$T$21:$T$120,1),MATCH(U8,'BASE CALCULS '!$V$20:$AD$20,0))*E8/12) -> 0 | AZ8: =IF(V8="aucune",0,INDEX(table_cot_manu,MATCH(G8,'BASE CALCULS '!$AF$21:$AF$120,1),MATCH(V8,'BASE CALCULS '!$AH$20:$AR$20,0)))*BA8 -> 0 | BA8: =IF(W8="1l",E8/12,IF(W8="1l1c",(E8+F8)/12,IF(W8="1l2c",(E8+F8*2)/12,IF(W8="2l",E8*2/12,IF(W8="2l1c",(E8*2+F8)/12,IF(W8="2l2c",(E8*2+F8*2)/12,IF(W8="2c",F8*2/12,IF(W8="1c",F8/12,0)))))))) -> 20 | BB8: =IF(X8="aucune",0,INDEX(table_cot_manu,MATCH(G8,'BASE CALCULS '!$AF$21:$AF$120,1),MATCH(X8,'BASE CALCULS '!$AH$20:$AR$20,0)))*BC8 -> 0 | BC8: =IF(Y8="1l",E8/12,IF(Y8="1l1c",(E8+F8)/12,IF(Y8="1l2c",(E8+F8*2)/12,IF(Y8="2l",E8*2/12,IF(Y8="2l1c",(E8*2+F8)/12,IF(Y8="2l2c",(E8*2+F8*2)/12,IF(Y8="2c",F8*2/12,IF(Y8="1c",F8/12,0)))))))) -> 8 | BD8: =IF(H8="",0,VLOOKUP(H8,volumepetitetaille,2)) -> 0 | BE8: =IF(Z8="aucun",0,VLOOKUP(Z8,table_chan,2)*BF8) -> 0 | BF8: =IF(AA8="1l",E8/12,IF(AA8="1l1c",(E8+F8)/12,IF(AA8="1l2c",(E8+F8*2)/12,IF(AA8="2l",E8*2/12,IF(AA8="2l1c",(E8*2+F8)/12,IF(AA8="2l2c",(E8*2+F8*2)/12,IF(AA8="2c",F8*2/12,IF(AA8="1c",F8/12,0)))))))) -> 16 | BG8: =IF(AB8="aucune",0,VLOOKUP(AC8,table_slot,2)*BH8) -> 0 | BH8: =AB8 -> aucune | BI8: =IF(AD8="aucun",0,AD8*(INDEX(table_trou,MATCH(AF8,'BASE CALCULS '!$BL$21:$BL$36,1),MATCH(AE8,'BASE CALCULS '!$BM$20:$CB$20,1)))) -> 0 | BJ8: =AD8 -> aucun | BK8: =IF(AG8="aucune",0,(INDEX(table_enc,MATCH(AH8,'BASE CALCULS '!$CD$21:$CD$38,1),MATCH(AI8,'BASE CALCULS '!$CF$20:$CU$20,1))))*BL8 -> 0 | BL8: =IF(AG8="1l",E8/12,IF(AG8="1l1c",(E8+F8)/12,IF(AG8="1l2c",(E8+F8*2)/12,IF(AG8="2l",E8*2/12,IF(AG8="2l1c",(E8*2+F8)/12,IF(AG8="2l2c",(E8*2+F8*2)/12,IF(AG8="2c",F8*2/12,IF(AG8="1c",F8/12,0)))))))) -> 0 | BM8: =+AJ8*$BM$7 -> 0 | BN8: =+AK8*$BN$7 -> 0 | BO8: =SUM(AM8:AZ8)+BB8+BD8+BE8+BG8+BI8+BK8+BM8+BN8 -> 121.86556 | BP8: =+$BP$7 -> 0.7 | BQ8: =+BO8/BP8+AL8+(H8*15) -> 372.26173 | BR8: =BQ8/$BR$7 -> 391.85446 | BS8: =BR8/$BS$7 -> 412.47838 | BT8: =+BS8/(E8*F8*G8/1728) -> 44.194112 | BU8: =+BS8/(E8*F8/144) -> 25.779898 | BV8: =+BS8/(E8/12) -> 51.559797 | BW8: =IF(OR(BX8="/ ea",BX8="/ piece"),ROUND(BS8,2),IF(OR(BX8="/ LF",BX8="/ plin"),ROUND(BV8,2),IF(OR(BX8="/ SF",BX8="/ pi2"),ROUND(BU8,2),IF(OR(BX8="/ CF",BX8="/ pi3"),ROUND(BT8,2),IF(OR(BX8="/ linM",BX8="/ Mlin"),ROUND(BV8/0.3048,2),IF(BX8="/ m2",ROUND(BU8*10.74,2),IF(BX8="/ m3",ROUND(BT8*35.32,2),35))))))) -> 412.48 | BX8: =+Cotation!X13 -> / ea | BY8: =+E8*F8*G8/1728 -> 9.3333333 | BZ8: =IF(BX8="/ ea",$BZ$7*BY8,IF(BX8="/ piece",$BZ$7*BY8,IF(BX8="/ LF",BY8/(E8/12)*$BZ$7,IF(BX8="/ SF",BY8/(E8*F8/144)*$BZ$7,IF(BX8="/ CF",BY8/(E8*F8*G8/1728)*$BZ$7,IF(BX8="/ LinM",BY8/(E8/12)*3.2808*$BZ$7,IF(BX8="/ m2",BY8/(E8*F8/144)*10.76*$BZ$7,IF(BX8="/ m3",BY8/(E8*F8*G8/1728)*35.36*$BZ$7,1)))))))) -> 2750 | CA8: =ROUND(BW8+BZ8,1) -> 3162.5 | CB8: =+BX8 -> / ea | CC8: =IF($BX8="/ ea",$BW8*$C8,IF($BX8="/ piece",$BW8*$C8,IF($BX8="/ LF",$C8*$BW8,IF($BX8="/ SF",$C8*$BW8,IF($BX8="/ CF",$C8*BW8,IF($BX8="/ LinM",$C8*BW8,IF($BX8="/ m2",$C8*$BW8,IF($BX$8="/ m3",$C8*$BW8,1)))))))) -> 412.48 | CD8: =+CA8*C8 -> 3162.5 | CE8: =+CD8-CC8 -> 2750.02 | CF8: =+E8/12 -> 8 | CG8: =+E8*F8/144 -> 16 | CH8: =ROUND(CA8*C8,1) -> 3162.5 | CI8: =ROUND(+BW8*C8,1) -> 412.5 | CL8: =AL8 -> 58.168083 | CM8: =AM8 -> 78.115556 | CN8: =AN8 -> 43.75 | CO8: =IF(OR(BX8="/ ea",BX8="/ piece"),ROUND(CU8,1),IF(OR(BX8="/ LF",BX8="/ plin"),ROUND(DA8,1),IF(OR(BX8="/ SF",BX8="/ pi2"),ROUND(CZ8,1),IF(OR(BX8="/ CF",BX8="/ pi3"),ROUND(CY8,1),IF(OR(BX8="/ linM",BX8="/ mlin"),ROUND(DA8/0.3048,1),IF(BX8="/ m2",ROUND(CZ8*10.74,1),IF(BX8="/ m3",ROUND(CY8*35.32,1),35))))))) -> 0 | CP8: =IF(OR(BX8="/ ea",BX8="/ piece"),ROUND(CV8,1),IF(OR(BX8="/ LF",BX8="/ plin"),ROUND(DE8,1),IF(OR(BX8="/ SF",BX8="/ pi2"),ROUND(DD8,1),IF(OR(BX8="/ CF",BX8="/ pi3"),ROUND(DC8,1),IF(OR(BX8="/ linM",BX8="/ mlin"),ROUND(DE8/0.3048,1),IF(BX8="/ m2",ROUND(DD8*10.74,1),IF(BX8="/ m3",ROUND(DC8*35.32,1),35))))))) -> 0 | CQ8: =IF(OR(BX8="/ ea",BX8="/ piece"),ROUND(CW8,1),IF(OR(BX8="/ LF",BX8="/ plin"),ROUND(DI8,1),IF(OR(BX8="/ SF",BX8="/ pi2"),ROUND(DH8,1),IF(OR(BX8="/ CF",BX8="/ pi3"),ROUND(DG8,1),IF(OR(BX8="/ linM",BX8="/ mlin"),ROUND(DI8/0.3048,1),IF(BX8="/ m2",ROUND(DH8*10.74,1),IF(BX8="/ m3",ROUND(DG8*35.32,1),35))))))) -> 0 | CR8: =SUM(CM8:CQ8)/60 -> 2.0310926 | CS8: =+CR8*C8 -> 2.0310926 | CU8: =+(AO8/2)+(AP8/2)+(N8*60)+(BE8/2)+(BK8/1.67) -> 0 | CV8: =+(AQ8/2)+(O8*60)+AV8+(AW8/2)+AX8+(AY8/1.5)+(AZ8/2)+(BB8/2) -> 0 | CW8: =AT8+AU8+BG8+BI8 -> 0 | CY8: =+CU8/(E8*F8*G8/1728) -> 0 | CZ8: =CU8/(E8*F8/144) -> 0 | DA8: =CU8/(E8/12) -> 0 | DC8: =+CV8/(E8*F8*G8/1728) -> 0 | DD8: =CV8/(E8*F8/144) -> 0 | DE8: =CV8/(E8/12) -> 0 | DG8: =+CW8/(E8*F8*G8/1728) -> 0 | DH8: =CW8/(E8*F8/144) -> 0 | DI8: =CW8/(E8/12) -> 0

Sheet BASE CALCULS 
A1: Taux horaire
A2: Scie 3,5 m | B2: 70 | E2: PETIT VOLUME | I2: ou_cote | J2: aucun | K2: 1l | L2: 1l1c | M2: 1l2c | N2: 2l | O2: 2l1c | P2: 2l2c | Q2: 2c | R2: 1c
A3: Scie 3 m | B3: 70 | I3: dim_chan | J3: aucun | K3: 0.25 | L3: 0.375 | M3: 0.5 | N3: 0.625 | O3: 0.75 | P3: 1 | Q3: 1.25 | R3: 1.5 | S3: =+R3+0.25 -> 1.75 | T3: =+S3+0.25 -> 2 | U3: =+T3+0.25 -> 2.25 | V3: =+U3+0.25 -> 2.5 | W3: =+V3+0.25 -> 2.75 | X3: =+W3+0.25 -> 3 | Y3: =+X3+0.25 -> 3.25 | Z3: =+Y3+0.25 -> 3.5 | ... AB3: =+AA3+0.25 -> 4
A4: Scie Falcon | B4: 70 | E4: VOLUME | F4: PRIX | I4: action_fin | J4: oui | K4: non
A5: Scie Terzago | B5: 80 | E5: 1e-06 | F5: 35 | I5: fin_des_auto | J5: aucune | K5: Meulé | L5: Flamée | M5: Brossée | N5: Jet de sable | O5: Poli mat | P5: Poli | Q5: Bouchardée | R5: Jet d'eau | S5: Antique
A6: Scie Predator | B6: 70 | E6: 0.5 | F6: 32 | I6: fin_des_man | J6: aucune | K6: Meulé | L6: Flamée | M6: Brossée | N6: Jet de sable | O6: Poli mat | P6: Poli | Q6: Bouchardée | R6: Jet d'eau | S6: Antique
A7: Spliteuse | B7: 100 | E7: 1 | F7: 29 | I7: fin_cote_man | J7: aucune | K7: Meulé | L7: Flamée | M7: Brossée | N7: Jet de sable | O7: Poli mat | P7: Poli | Q7: Bouchardée | R7: Split | S7: Rock Face | T7: Jet d'eau | U7: Antique
A8: Bimatech | B8: 70 | E8: 1.5 | F8: 25 | I8: nb_trou | J8: aucun | K8: 1 | L8: 2 | M8: 3 | N8: 4 | O8: 5 | P8: 6 | Q8: 7 | R8: 8 | S8: 9 | T8: 10 | U8: 11 | V8: 12 | W8: 13 | X8: 14 | Y8: 15 | Z8: 16
A9: C4 | B9: 80 | E9: 2 | F9: 20 | I9: diam_trou | J9: 0.125 | K9: =+J9+0.125 -> 0.25 | L9: =+K9+0.125 -> 0.375 | M9: =+L9+0.125 -> 0.5 | N9: =+M9+0.125 -> 0.625 | O9: =+N9+0.125 -> 0.75 | P9: =+O9+0.125 -> 0.875 | Q9: =+P9+0.125 -> 1 | R9: =+Q9+0.125 -> 1.125 | ... Y9: =+X9+0.125 -> 2
A10: Sphera | B10: 100 | E10: 2.5 | F10: 15 | I10: prof_trou | J10: 0.5 | K10: =+J10+0.5 -> 1 | L10: =+K10+0.5 -> 1.5 | M10: =+L10+0.5 -> 2 | N10: =+M10+0.5 -> 2.5 | O10: =+N10+0.5 -> 3 | P10: =+O10+0.5 -> 3.5 | Q10: =+P10+0.5 -> 4 | R10: =+Q10+0.5 -> 4.5 | ... Y10: =+X10+0.5 -> 8
A11: Poste finition 1 | B11: 50 | E11: 3 | F11: 12 | I11: nb_slot | J11: aucune | K11: 1 | L11: 2 | M11: 3 | N11: 4 | O11: 5 | P11: 6 | Q11: 7 | R11: 8 | S11: 9 | T11: 10
A12: Poste finition 2 | B12: 50 | E12: 3.5 | F12: 9 | I12: long_slot | J12: 1 | K12: 2 | L12: 3 | M12: 4 | N12: 5 | O12: 6 | P12: 7 | Q12: 8 | R12: 9 | S12: 10
A13: Poste finition 3 | B13: 50 | E13: 4 | F13: 7 | I13: encoche_largeur | J13: 0.25 | K13: 0.5 | L13: 0.75 | M13: 1 | N13: 1.25 | O13: 1.5 | P13: 1.75 | Q13: 2 | R13: 2.25 | S13: 2.5 | T13: 2.75 | U13: 3 | V13: 3.25 | W13: 3.5 | X13: 3.75 | Y13: 4
A14: Poste finition 4 | B14: 70 | E14: 4.5 | F14: 5 | I14: prof_encoche_ | J14: 0.25 | K14: 0.375 | L14: 0.5 | M14: 0.625 | N14: 0.75 | O14: 0.875 | P14: 1 | Q14: 1.25 | R14: 1.5 | S14: 1.75 | T14: 2 | U14: 2.25 | V14: 2.5 | W14: 2.75 | X14: 3 | Y14: 3.25 | Z14: 3.5 | AA14: 3.75 | AB14: 4
E15: 5 | F15: 0 | I15: encoche_ | J15: aucune | K15: 1l | L15: 1l1c | M15: 1l2c | N15: 2l | O15: 2l1c | P15: 2l2c | Q15: 2c | R15: 1c
CD16: CF21 = 30 secondes/4Pilin de ¼" x ¼" | CG16: =30/4 -> 7.5 | CH16: =60/CG16 -> 8 | CI16: =+CH16*60 -> 480 | CJ16: =100/CI16 -> 0.20833333 | CO16: Coeff diminution difficulté
CO17: 1.05 | CP17: 1.1 | CQ17: 1.12 | CR17: 1.14 | CS17: 1.16 | CT17: 1.17 | CU17: 1.18
A18: Sciage primaire | D18: Sciage Secondaire | F18: 3.75 | H18: Finition dessus automatique | J18: 4.5 | K18: 2 | L18: 4.5 | M18: 4 | N18: 5 | O18: 5.5 | P18: 3.75 | Q18: 4.25 | R18: 6 | T18: Finition dessus manuel | V18: =J18*1.25 -> 5.625 | W18: =+K18*1.5 -> 3 | X18: =+L18*1.5 -> 6.75 | Y18: =+M18*1.5 -> 6 | Z18: =+N18*3 -> 15 | AA18: =+O18*3.5 -> 19.25 | AB18: =+P18*1.5 -> 5.625 | AC18: =+Q18*1.5 -> 6.375 | AD18: =+R18*3 -> 18 | AF18: Finition coté manuel | AH18: =V18*1.25 -> 7.03125 | AI18: =W18*1.25 -> 3.75 | AJ18: =X18 -> 6.75 | AK18: =Y18 -> 6 | AL18: =Z18*1.5 -> 22.5 | AM18: =AA18*1.5 -> 28.875 | AN18: =AB18 -> 5.625 | AO18: 2 | AP18: 5 | AQ18: =AC18*1.5 -> 9.5625 | AR18: =AD18*1.5 -> 27 | AT18: Chanfrein | AU18: 0.15 | AW18: Finition manuel chanfrein | AY18: 2 | AZ18: 3 | BA18: 5 | BB18: 6 | BC18: 30 | BD18: 40 | BE18: 20 | BF18: 7 | BG18: 10 | BI18: SLOT_ | BJ18: 0.2 | BL18: TROU | BM18: 5 | BN18: =+BM18+0.5 -> 5.5 | BO18: =+BN18+0.5 -> 6 | BP18: =+BO18+0.5 -> 6.5 | BQ18: =+BP18+0.5 -> 7 | BR18: =+BQ18+0.5 -> 7.5 | BS18: =+BR18+0.5 -> 8 | BT18: =+BS18+0.5 -> 8.5 | BU18: =+BT18+0.5 -> 9 | BV18: =+BU18+0.5 -> 9.5 | BW18: =+BV18+0.5*1.5 -> 10.25 | BX18: =+BW18+0.5*1.5 -> 11 | BY18: =+BX18+0.5*1.5 -> 11.75 | BZ18: =+BY18+0.5*1.5 -> 12.5 | CA18: =+BZ18+0.5*1.5 -> 13.25 | CB18: =+CA18+0.5*1.5 -> 14 | CD18: Encoche | CE18: Coeff diff. | CF18: =$B$10/CE21 -> 3.3333333 | CG18: =CF18 -> 3.3333333 | CH18: =CG18 -> 3.3333333 | CI18: =CH18 -> 3.3333333 | CJ18: =CI18 -> 3.3333333 | CK18: =CJ18 -> 3.3333333 | CL18: =CK18 -> 3.3333333 | CM18: =CL18 -> 3.3333333 | CN18: =CM18 -> 3.3333333 | ... CU18: =CT18 -> 3.3333333
BI19: coeff
A20: Epaisseur | B20: Ratio Tranche | D20: Epaisseur | E20: Coeff | F20: prix au pi2 | H20: Fini/ Épaisseur | I20: Coeff | J20: Meulé | K20: Flamée | L20: Brossée | M20: Jet de sable | N20: Poli mat | O20: Poli | P20: Bouchardée | Q20: Jet d'eau | R20: Antique | T20: Fini/ Épaisseur | U20: Coeff | V20: Meulé | W20: Flamée | X20: Brossée | Y20: Jet de sable | Z20: Poli mat | AA20: Poli | AB20: Bouchardée | AC20: Jet d'eau | AD20: Antique | AF20: Fini/ Épaisseur | AG20: Coeff | AH20: Meulé | AI20: Flamée | AJ20: Brossée | AK20: Jet de sable | AL20: Poli mat | AM20: Poli | AN20: Bouchardée | AO20: Split | AP20: Rock Face | AQ20: Jet d'eau | AR20: Antique | AT20: Largeur | AU20: prix au pl | AW20: Fini/ dimension | AX20: Coeff | AY20: Meulé | AZ20: Flamée | BA20: Brossée | BB20: Jet de sable | BC20: Poli mat | BD20: Poli | BE20: Bouchardée | BF20: Jet d'eau | BG20: Antique | BI20: Longueur | BJ20: prix à l'unité | BL20: diam / profondeur | BM20: 0.125 | BN20: =+BM20+0.125 -> 0.25 | BO20: =+BN20+0.125 -> 0.375 | BP20: =+BO20+0.125 -> 0.5 | BQ20: =+BP20+0.125 -> 0.625 | BR20: =+BQ20+0.125 -> 0.75 | BS20: =+BR20+0.125 -> 0.875 | BT20: =+BS20+0.125 -> 1 | BU20: =+BT20+0.125 -> 1.125 | ... CB20: =+CA20+0.125 -> 2 | CD20: Largeur/ Hauteur | CF20: 0.25 | CG20: 0.5 | CH20: 0.75 | CI20: 1 | CJ20: 1.25 | CK20: 1.5 | CL20: 1.75 | CM20: 2 | CN20: 2.25 | CO20: 2.5 | CP20: 2.75 | CQ20: 3 | CR20: 3.25 | CS20: 3.5 | CT20: 3.75 | CU20: 4
A21: 0.1 | B21: 1.1 | D21: 0.75 | E21: 1.8 | F21: =+$F$18*E21 -> 6.75 | H21: 1 | I21: 2 | J21: =+J$18*$H21/12*$I21 -> 0.75 | K21: =+K$18*$H21/12*$I21 -> 0.33333333 | L21: =+L$18*$H21/12*$I21 -> 0.75 | M21: =+M$18*$H21/12*$I21 -> 0.66666667 | N21: =+N$18*$H21/12*$I21 -> 0.83333333 | O21: =+O$18*$H21/12*$I21 -> 0.91666667 | P21: =+P$18*$H21/12*$I21 -> 0.625 | Q21: =+Q$18*$H21/12*$I21 -> 0.70833333 | R21: =+R$18*$H21/12*$I21 -> 1 | T21: 1 | U21: 2 | V21: =+V$18*$T21/12*$U21 -> 0.9375 | W21: =+W$18*$T21/12*$U21 -> 0.5 | X21: =+X$18*$T21/12*$U21 -> 1.125 | Y21: =+Y$18*$T21/12*$U21 -> 1 | Z21: =+Z$18*$T21/12*$U21 -> 2.5 | AA21: =+AA$18*$T21/12*$U21 -> 3.2083333 | AB21: =+AB$18*$T21/12*$U21 -> 0.9375 | AC21: =+AC$18*$T21/12*$U21 -> 1.0625 | AD21: =+AD$18*$T21/12*$U21 -> 3 | AF21: 1 | AG21: 2 | AH21: =+AH$18*$AF21/12*$AG21 -> 1.171875 | AI21: =+AI$18*$AF21/12*$AG21 -> 0.625 | AJ21: =+AJ$18*$AF21/12*$AG21 -> 1.125 | AK21: =+AK$18*$AF21/12*$AG21 -> 1 | AL21: =+AL$18*$AF21/12*$AG21 -> 3.75 | AM21: =+AM$18*$AF21/12*$AG21 -> 4.8125 | AN21: =+AN$18*$AF21/12*$AG21 -> 0.9375 | AO21: =+AO$18*$AF21/12*$AG21 -> 0.33333333 | ... AR21: =+AR$18*$AF21/12*$AG21 -> 4.5 | AT21: 0.25 | AU21: 3.75 | AW21: 0.25 | AX21: 2 | AY21: =+AY$18*$H21/12*$I21 -> 0.33333333 | AZ21: =+AZ$18*$H21/12*$I21 -> 0.5 | BA21: =+BA$18*$H21/12*$I21 -> 0.83333333 | BB21: =+BB$18*$H21/12*$I21 -> 1 | BC21: =+BC$18*$H21/12*$I21 -> 5 | BD21: =+BD$18*$H21/12*$I21 -> 6.6666667 | BE21: =+BE$18*$H21/12*$I21 -> 3.3333333 | BF21: =+BF$18*$H21/12*$I21 -> 1.1666667 | BG21: =+BG$18*$H21/12*$I21 -> 1.6666667 | BI21: 1 | BJ21: 3 | BL21: 0.5 | BM21: =+BM$18*$BL21 -> 2.5 | BN21: =+BN$18*$BL21 -> 2.75 | BO21: =+BO$18*$BL21 -> 3 | BP21: =+BP$18*$BL21 -> 3.25 | BQ21: =+BQ$18*$BL21 -> 3.5 | BR21: =+BR$18*$BL21 -> 3.75 | BS21: =+BS$18*$BL21 -> 4 | BT21: =+BT$18*$BL21 -> 4.25 | ... CB21: =+CB$18*$BL21 -> 7 | CD21: 0.25 | CE21: 30 | CF21: =+($CF$20*CD21)*$CF$18 -> 0.20833333 | CG21: =+($CG$20*CD21)*$CG$18 -> 0.41666667 | CH21: =+($CH$20*CD21)*$CH$18 -> 0.625 | CI21: =+($CI$20*CD21)*$CI$18 -> 0.83333333 | CJ21: =+($CJ$20*CD21)*$CJ$18 -> 1.0416667 | CK21: =+($CK$20*CD21)*$CK$18 -> 1.25 | CL21: =+($CL$20*CD21)*$CL$18 -> 1.4583333 | CM21: =+($CM$20*CD21)*$CM$18 -> 1.6666667 | CN21: =+($CN$20*CD21)*$CN$18 -> 1.875 | CO21: =+($CO$20*CD21)*$CO$18 -> 2.0833333 | CP21: =+($CP$20*CD21)*$CP$18 -> 2.2916667 | CQ21: =+($CQ$20*CD21)*$CQ$18 -> 2.5 | CR21: =+($CR$20*CD21)*$CR$18 -> 2.7083333 | CS21: =+($CS$20*CD21)*$CS$18 -> 2.9166667 | CT21: =+($CT$20*CD21)*$CT$18 -> 3.125 | CU21: =+($CU$20*CD21)*$CU$18 -> 3.3333333
A22: 1.25 | B22: 1.0277778 | D22: 1.25 | E22: 1.6 | F22: =+$F$18*E22 -> 6 | H22: 2 | I22: 1.6 | J22: =+J$18*$H22/12*$I22 -> 1.2 | K22: =+K$18*$H22/12*$I22 -> 0.53333333 | L22: =+L$18*$H22/12*$I22 -> 1.2 | M22: =+M$18*$H22/12*$I22 -> 1.0666667 | N22: =+N$18*$H22/12*$I22 -> 1.3333333 | O22: =+O$18*$H22/12*$I22 -> 1.4666667 | P22: =+P$18*$H22/12*$I22 -> 1 | Q22: =+Q$18*$H22/12*$I22 -> 1.1333333 | R22: =+R$18*$H22/12*$I22 -> 1.6 | T22: 2 | U22: 1.6 | V22: =+V$18*$H22/12*$I22 -> 1.5 | W22: =+W$18*$H22/12*$I22 -> 0.8 | X22: =+X$18*$H22/12*$I22 -> 1.8 | Y22: =+Y$18*$H22/12*$I22 -> 1.6 | Z22: =+Z$18*$H22/12*$I22 -> 4 | AA22: =+AA$18*$H22/12*$I22 -> 5.1333333 | AB22: =+AB$18*$H22/12*$I22 -> 1.5 | AC22: =+AC$18*$H22/12*$I22 -> 1.7 | AD22: =+AD$18*$H22/12*$I22 -> 4.8 | AF22: 2 | AG22: 1.6 | AH22: =+AH$18*$AF22/12*$AG22 -> 1.875 | AI22: =+AI$18*$AF22/12*$AG22 -> 1 | AJ22: =+AJ$18*$AF22/12*$AG22 -> 1.8 | AK22: =+AK$18*$AF22/12*$AG22 -> 1.6 | AL22: =+AL$18*$AF22/12*$AG22 -> 6 | AM22: =+AM$18*$AF22/12*$AG22 -> 7.7 | AN22: =+AN$18*$AF22/12*$AG22 -> 1.5 | AO22: =+AO$18*$AF22/12*$AG22 -> 0.53333333 | ... AR22: =+AR$18*$AF22/12*$AG22 -> 7.2 | AT22: 0.375 | AU22: =+AU21+(AT22/AT21*AU21*$AU$18) -> 4.59375 | AW22: 0.375 | AX22: 1.6 | AY22: =+AY$18*$H22/12*$I22 -> 0.53333333 | AZ22: =+AZ$18*$H22/12*$I22 -> 0.8 | BA22: =+BA$18*$H22/12*$I22 -> 1.3333333 | BB22: =+BB$18*$H22/12*$I22 -> 1.6 | BC22: =+BC$18*$H22/12*$I22 -> 8 | BD22: =+BD$18*$H22/12*$I22 -> 10.666667 | BE22: =+BE$18*$H22/12*$I22 -> 5.3333333 | BF22: =+BF$18*$H22/12*$I22 -> 1.8666667 | BG22: =+BG$18*$H22/12*$I22 -> 2.6666667 | BI22: 2 | BJ22: =+BJ21+(BI22/BI21*BJ21*$BJ$18) -> 4.2 | BL22: =+BL21+0.5 -> 1 | BM22: =+BM$18*$BL22 -> 5 | BN22: =+BN$18*$BL22 -> 5.5 | BO22: =+BO$18*$BL22 -> 6 | BP22: =+BP$18*$BL22 -> 6.5 | BQ22: =+BQ$18*$BL22 -> 7 | BR22: =+BR$18*$BL22 -> 7.5 | BS22: =+BS$18*$BL22 -> 8 | BT22: =+BT$18*$BL22 -> 8.5 | ... CB22: =+CB$18*$BL22 -> 14 | CD22: 0.375 | CE22: SI COEFF AUGMENTE = PRIX BAISSE (DONC PEUT ÊTRE CHANGÉ À PARTIR DE 3" X 3" ENVIRON) | CF22: =+($CF$20*CD22)*$CF$18 -> 0.3125 | CG22: =+($CG$20*CD22)*$CG$18 -> 0.625 | CH22: =+($CH$20*CD22)*$CH$18 -> 0.9375 | CI22: =+($CI$20*CD22)*$CI$18 -> 1.25 | CJ22: =+($CJ$20*CD22)*$CJ$18 -> 1.5625 | CK22: =+($CK$20*CD22)*$CK$18 -> 1.875 | CL22: =+($CL$20*CD22)*$CL$18 -> 2.1875 | CM22: =+($CM$20*CD22)*$CM$18 -> 2.5 | CN22: =+($CN$20*CD22)*$CN$18 -> 2.8125 | CO22: =+($CO$20*CD22)*$CO$18 -> 3.125 | CP22: =+($CP$20*CD22)*$CP$18 -> 3.4375 | CQ22: =+($CQ$20*CD22)*$CQ$18 -> 3.75 | CR22: =+($CR$20*CD22)*$CR$18 -> 4.0625 | CS22: =+($CS$20*CD22)*$CS$18 -> 4.375 | CT22: =+($CT$20*CD22)*$CT$18 -> 4.6875 | CU22: =+($CU$20*CD22)*$CU$18 -> 5
A23: 2 | B23: 1.0444444 | D23: 1.75 | E23: 1.4 | F23: =+$F$18*E23 -> 5.25 | H23: 3 | I23: 1.4 | J23: =+J$18*$H23/12*$I23 -> 1.575 | K23: =+K$18*$H23/12*$I23 -> 0.7 | L23: =+L$18*$H23/12*$I23 -> 1.575 | M23: =+M$18*$H23/12*$I23 -> 1.4 | N23: =+N$18*$H23/12*$I23 -> 1.75 | O23: =+O$18*$H23/12*$I23 -> 1.925 | P23: =+P$18*$H23/12*$I23 -> 1.3125 | Q23: =+Q$18*$H23/12*$I23 -> 1.4875 | R23: =+R$18*$H23/12*$I23 -> 2.1 | T23: 3 | U23: 1.4 | V23: =+V$18*$H23/12*$I23 -> 1.96875 | W23: =+W$18*$H23/12*$I23 -> 1.05 | X23: =+X$18*$H23/12*$I23 -> 2.3625 | Y23: =+Y$18*$H23/12*$I23 -> 2.1 | Z23: =+Z$18*$H23/12*$I23 -> 5.25 | AA23: =+AA$18*$H23/12*$I23 -> 6.7375 | AB23: =+AB$18*$H23/12*$I23 -> 1.96875 | AC23: =+AC$18*$H23/12*$I23 -> 2.23125 | AD23: =+AD$18*$H23/12*$I23 -> 6.3 | AF23: 3 | AG23: 1.4 | AH23: =+AH$18*$AF23/12*$AG23 -> 2.4609375 | AI23: =+AI$18*$AF23/12*$AG23 -> 1.3125 | AJ23: =+AJ$18*$AF23/12*$AG23 -> 2.3625 | AK23: =+AK$18*$AF23/12*$AG23 -> 2.1 | AL23: =+AL$18*$AF23/12*$AG23 -> 7.875 | AM23: =+AM$18*$AF23/12*$AG23 -> 10.10625 | AN23: =+AN$18*$AF23/12*$AG23 -> 1.96875 | AO23: =+AO$18*$AF23/12*$AG23 -> 0.7 | ... AR23: =+AR$18*$AF23/12*$AG23 -> 9.45 | AT23: 0.5 | AU23: =+AU22+(AT23/AT22*AU22*$AU$18) -> 5.5125 | AW23: 0.5 | AX23: 1.4 | AY23: =+AY$18*$H23/12*$I23 -> 0.7 | AZ23: =+AZ$18*$H23/12*$I23 -> 1.05 | BA23: =+BA$18*$H23/12*$I23 -> 1.75 | BB23: =+BB$18*$H23/12*$I23 -> 2.1 | BC23: =+BC$18*$H23/12*$I23 -> 10.5 | BD23: =+BD$18*$H23/12*$I23 -> 14 | BE23: =+BE$18*$H23/12*$I23 -> 7 | BF23: =+BF$18*$H23/12*$I23 -> 2.45 | BG23: =+BG$18*$H23/12*$I23 -> 3.5 | BI23: 3 | BJ23: =+BJ22+(BI23/BI22*BJ22*$BJ$18) -> 5.46 | BL23: =+BL22+0.5 -> 1.5 | BM23: =+BM$18*$BL23 -> 7.5 | BN23: =+BN$18*$BL23 -> 8.25 | BO23: =+BO$18*$BL23 -> 9 | BP23: =+BP$18*$BL23 -> 9.75 | BQ23: =+BQ$18*$BL23 -> 10.5 | BR23: =+BR$18*$BL23 -> 11.25 | BS23: =+BS$18*$BL23 -> 12 | BT23: =+BT$18*$BL23 -> 12.75 | ... CB23: =+CB$18*$BL23 -> 21 | CD23: 0.5 | CF23: =+($CF$20*CD23)*$CF$18 -> 0.41666667 | CG23: =+($CG$20*CD23)*$CG$18 -> 0.83333333 | CH23: =+($CH$20*CD23)*$CH$18 -> 1.25 | CI23: =+($CI$20*CD23)*$CI$18 -> 1.6666667 | CJ23: =+($CJ$20*CD23)*$CJ$18 -> 2.0833333 | CK23: =+($CK$20*CD23)*$CK$18 -> 2.5 | CL23: =+($CL$20*CD23)*$CL$18 -> 2.9166667 | CM23: =+($CM$20*CD23)*$CM$18 -> 3.3333333 | CN23: =+($CN$20*CD23)*$CN$18 -> 3.75 | CO23: =+($CO$20*CD23)*$CO$18 -> 4.1666667 | CP23: =+($CP$20*CD23)*$CP$18 -> 4.5833333 | CQ23: =+($CQ$20*CD23)*$CQ$18 -> 5 | CR23: =+($CR$20*CD23)*$CR$18 -> 5.4166667 | CS23: =+($CS$20*CD23)*$CS$18 -> 5.8333333 | CT23: =+($CT$20*CD23)*$CT$18 -> 6.25 | CU23: =+($CU$20*CD23)*$CU$18 -> 6.6666667
A24: 3 | B24: 1.0666667 | D24: 2 | E24: 1.2 | F24: =+$F$18*E24 -> 4.5 | H24: 4 | I24: 1.2 | J24: =+J$18*$H24/12*$I24 -> 1.8 | K24: =+K$18*$H24/12*$I24 -> 0.8 | L24: =+L$18*$H24/12*$I24 -> 1.8 | M24: =+M$18*$H24/12*$I24 -> 1.6 | N24: =+N$18*$H24/12*$I24 -> 2 | O24: =+O$18*$H24/12*$I24 -> 2.2 | P24: =+P$18*$H24/12*$I24 -> 1.5 | Q24: =+Q$18*$H24/12*$I24 -> 1.7 | R24: =+R$18*$H24/12*$I24 -> 2.4 | T24: 4 | U24: 1.2 | V24: =+V$18*$H24/12*$I24 -> 2.25 | W24: =+W$18*$H24/12*$I24 -> 1.2 | X24: =+X$18*$H24/12*$I24 -> 2.7 | Y24: =+Y$18*$H24/12*$I24 -> 2.4 | Z24: =+Z$18*$H24/12*$I24 -> 6 | AA24: =+AA$18*$H24/12*$I24 -> 7.7 | AB24: =+AB$18*$H24/12*$I24 -> 2.25 | AC24: =+AC$18*$H24/12*$I24 -> 2.55 | AD24: =+AD$18*$H24/12*$I24 -> 7.2 | AF24: 4 | AG24: 1.2 | AH24: =+AH$18*$AF24/12*$AG24 -> 2.8125 | AI24: =+AI$18*$AF24/12*$AG24 -> 1.5 | AJ24: =+AJ$18*$AF24/12*$AG24 -> 2.7 | AK24: =+AK$18*$AF24/12*$AG24 -> 2.4 | AL24: =+AL$18*$AF24/12*$AG24 -> 9 | AM24: =+AM$18*$AF24/12*$AG24 -> 11.55 | AN24: =+AN$18*$AF24/12*$AG24 -> 2.25 | AO24: =+AO$18*$AF24/12*$AG24 -> 0.8 | ... AR24: =+AR$18*$AF24/12*$AG24 -> 10.8 | AT24: 0.625 | AU24: =+AU23+(AT24/AT23*AU23*$AU$18) -> 6.5460937 | AW24: 0.625 | AX24: 1.2 | AY24: =+AY$18*$H24/12*$I24 -> 0.8 | AZ24: =+AZ$18*$H24/12*$I24 -> 1.2 | BA24: =+BA$18*$H24/12*$I24 -> 2 | BB24: =+BB$18*$H24/12*$I24 -> 2.4 | BC24: =+BC$18*$H24/12*$I24 -> 12 | BD24: =+BD$18*$H24/12*$I24 -> 16 | BE24: =+BE$18*$H24/12*$I24 -> 8 | BF24: =+BF$18*$H24/12*$I24 -> 2.8 | BG24: =+BG$18*$H24/12*$I24 -> 4 | BI24: 4 | BJ24: =+BJ23+(BI24/BI23*BJ23*$BJ$18) -> 6.916 | BL24: =+BL23+0.5 -> 2 | BM24: =+BM$18*$BL24 -> 10 | BN24: =+BN$18*$BL24 -> 11 | BO24: =+BO$18*$BL24 -> 12 | BP24: =+BP$18*$BL24 -> 13 | BQ24: =+BQ$18*$BL24 -> 14 | BR24: =+BR$18*$BL24 -> 15 | BS24: =+BS$18*$BL24 -> 16 | BT24: =+BT$18*$BL24 -> 17 | ... CB24: =+CB$18*$BL24 -> 28 | CD24: 0.625 | CF24: =+($CF$20*CD24)*$CF$18 -> 0.52083333 | CG24: =+($CG$20*CD24)*$CG$18 -> 1.0416667 | CH24: =+($CH$20*CD24)*$CH$18 -> 1.5625 | CI24: =+($CI$20*CD24)*$CI$18 -> 2.0833333 | CJ24: =+($CJ$20*CD24)*$CJ$18 -> 2.6041667 | CK24: =+($CK$20*CD24)*$CK$18 -> 3.125 | CL24: =+($CL$20*CD24)*$CL$18 -> 3.6458333 | CM24: =+($CM$20*CD24)*$CM$18 -> 4.1666667 | CN24: =+($CN$20*CD24)*$CN$18 -> 4.6875 | CO24: =+($CO$20*CD24)*$CO$18 -> 5.2083333 | CP24: =+($CP$20*CD24)*$CP$18 -> 5.7291667 | CQ24: =+($CQ$20*CD24)*$CQ$18 -> 6.25 | CR24: =+($CR$20*CD24)*$CR$18 -> 6.7708333 | CS24: =+($CS$20*CD24)*$CS$18 -> 7.2916667 | CT24: =+($CT$20*CD24)*$CT$18 -> 7.8125 | CU24: =+($CU$20*CD24)*$CU$18 -> 8.3333333
A25: 4 | B25: 1.0888889 | D25: 2.5 | E25: 1 | F25: =+$F$18*E25 -> 3.75 | H25: 5 | I25: 1 | J25: =+J$18*$H25/12*$I25 -> 1.875 | K25: =+K$18*$H25/12*$I25 -> 0.83333333 | L25: =+L$18*$H25/12*$I25 -> 1.875 | M25: =+M$18*$H25/12*$I25 -> 1.6666667 | N25: =+N$18*$H25/12*$I25 -> 2.0833333 | O25: =+O$18*$H25/12*$I25 -> 2.2916667 | P25: =+P$18*$H25/12*$I25 -> 1.5625 | Q25: =+Q$18*$H25/12*$I25 -> 1.7708333 | R25: =+R$18*$H25/12*$I25 -> 2.5 | T25: 5 | U25: 1 | V25: =+V$18*$H25/12*$I25 -> 2.34375 | W25: =+W$18*$H25/12*$I25 -> 1.25 | X25: =+X$18*$H25/12*$I25 -> 2.8125 | Y25: =+Y$18*$H25/12*$I25 -> 2.5 | Z25: =+Z$18*$H25/12*$I25 -> 6.25 | AA25: =+AA$18*$H25/12*$I25 -> 8.0208333 | AB25: =+AB$18*$H25/12*$I25 -> 2.34375 | AC25: =+AC$18*$H25/12*$I25 -> 2.65625 | AD25: =+AD$18*$H25/12*$I25 -> 7.5 | AF25: 5 | AG25: 1 | AH25: =+AH$18*$AF25/12*$AG25 -> 2.9296875 | AI25: =+AI$18*$AF25/12*$AG25 -> 1.5625 | AJ25: =+AJ$18*$AF25/12*$AG25 -> 2.8125 | AK25: =+AK$18*$AF25/12*$AG25 -> 2.5 | AL25: =+AL$18*$AF25/12*$AG25 -> 9.375 | AM25: =+AM$18*$AF25/12*$AG25 -> 12.03125 | AN25: =+AN$18*$AF25/12*$AG25 -> 2.34375 | AO25: =+AO$18*$AF25/12*$AG25 -> 0.83333333 | ... AR25: =+AR$18*$AF25/12*$AG25 -> 11.25 | AT25: 0.75 | AU25: =+AU24+(AT25/AT24*AU24*$AU$18) -> 7.7243906 | AW25: 0.75 | AX25: 1 | AY25: =+AY$18*$H25/12*$I25 -> 0.83333333 | AZ25: =+AZ$18*$H25/12*$I25 -> 1.25 | BA25: =+BA$18*$H25/12*$I25 -> 2.0833333 | BB25: =+BB$18*$H25/12*$I25 -> 2.5 | BC25: =+BC$18*$H25/12*$I25 -> 12.5 | BD25: =+BD$18*$H25/12*$I25 -> 16.666667 | BE25: =+BE$18*$H25/12*$I25 -> 8.3333333 | BF25: =+BF$18*$H25/12*$I25 -> 2.9166667 | BG25: =+BG$18*$H25/12*$I25 -> 4.1666667 | BI25: 5 | BJ25: =+BJ24+(BI25/BI24*BJ24*$BJ$18) -> 8.645 | BL25: =+BL24+0.5 -> 2.5 | BM25: =+BM$18*$BL25 -> 12.5 | BN25: =+BN$18*$BL25 -> 13.75 | BO25: =+BO$18*$BL25 -> 15 | BP25: =+BP$18*$BL25 -> 16.25 | BQ25: =+BQ$18*$BL25 -> 17.5 | BR25: =+BR$18*$BL25 -> 18.75 | BS25: =+BS$18*$BL25 -> 20 | BT25: =+BT$18*$BL25 -> 21.25 | ... CB25: =+CB$18*$BL25 -> 35 | CD25: 0.75 | CF25: =+($CF$20*CD25)*$CF$18 -> 0.625 | CG25: =+($CG$20*CD25)*$CG$18 -> 1.25 | CH25: =+($CH$20*CD25)*$CH$18 -> 1.875 | CI25: =+($CI$20*CD25)*$CI$18 -> 2.5 | CJ25: =+($CJ$20*CD25)*$CJ$18 -> 3.125 | CK25: =+($CK$20*CD25)*$CK$18 -> 3.75 | CL25: =+($CL$20*CD25)*$CL$18 -> 4.375 | CM25: =+($CM$20*CD25)*$CM$18 -> 5 | CN25: =+($CN$20*CD25)*$CN$18 -> 5.625 | CO25: =+($CO$20*CD25)*$CO$18 -> 6.25 | CP25: =+($CP$20*CD25)*$CP$18 -> 6.875 | CQ25: =+($CQ$20*CD25)*$CQ$18 -> 7.5 | CR25: =+($CR$20*CD25)*$CR$18 -> 8.125 | CS25: =+($CS$20*CD25)*$CS$18 -> 8.75 | CT25: =+($CT$20*CD25)*$CT$18 -> 9.375 | CU25: =+($CU$20*CD25)*$CU$18 -> 10
A26: 5 | B26: 1.1111111 | D26: 3 | E26: 1 | F26: =+$F$18*E26 -> 3.75 | H26: 6 | I26: 1 | J26: =+J$18*$H26/12*$I26 -> 2.25 | K26: =+K$18*$H26/12*$I26 -> 1 | L26: =+L$18*$H26/12*$I26 -> 2.25 | M26: =+M$18*$H26/12*$I26 -> 2 | N26: =+N$18*$H26/12*$I26 -> 2.5 | O26: =+O$18*$H26/12*$I26 -> 2.75 | P26: =+P$18*$H26/12*$I26 -> 1.875 | Q26: =+Q$18*$H26/12*$I26 -> 2.125 | R26: =+R$18*$H26/12*$I26 -> 3 | T26: 6 | U26: 1 | V26: =+V$18*$H26/12*$I26 -> 2.8125 | W26: =+W$18*$H26/12*$I26 -> 1.5 | X26: =+X$18*$H26/12*$I26 -> 3.375 | Y26: =+Y$18*$H26/12*$I26 -> 3 | Z26: =+Z$18*$H26/12*$I26 -> 7.5 | AA26: =+AA$18*$H26/12*$I26 -> 9.625 | AB26: =+AB$18*$H26/12*$I26 -> 2.8125 | AC26: =+AC$18*$H26/12*$I26 -> 3.1875 | AD26: =+AD$18*$H26/12*$I26 -> 9 | AF26: 6 | AG26: 1 | AH26: =+AH$18*$AF26/12*$AG26 -> 3.515625 | AI26: =+AI$18*$AF26/12*$AG26 -> 1.875 | AJ26: =+AJ$18*$AF26/12*$AG26 -> 3.375 | AK26: =+AK$18*$AF26/12*$AG26 -> 3 | AL26: =+AL$18*$AF26/12*$AG26 -> 11.25 | AM26: =+AM$18*$AF26/12*$AG26 -> 14.4375 | AN26: =+AN$18*$AF26/12*$AG26 -> 2.8125 | AO26: =+AO$18*$AF26/12*$AG26 -> 1 | ... AR26: =+AR$18*$AF26/12*$AG26 -> 13.5 | AT26: 1 | AU26: =+AU25+(AT26/AT25*AU25*$AU$18) -> 9.2692688 | AW26: 1 | AX26: 1 | AY26: =+AY$18*$H26/12*$I26 -> 1 | AZ26: =+AZ$18*$H26/12*$I26 -> 1.5 | BA26: =+BA$18*$H26/12*$I26 -> 2.5 | BB26: =+BB$18*$H26/12*$I26 -> 3 | BC26: =+BC$18*$H26/12*$I26 -> 15 | BD26: =+BD$18*$H26/12*$I26 -> 20 | BE26: =+BE$18*$H26/12*$I26 -> 10 | BF26: =+BF$18*$H26/12*$I26 -> 3.5 | BG26: =+BG$18*$H26/12*$I26 -> 5 | BI26: 6 | BJ26: =+BJ25+(BI26/BI25*BJ25*$BJ$18) -> 10.7198 | BL26: =+BL25+0.5 -> 3 | BM26: =+BM$18*$BL26 -> 15 | BN26: =+BN$18*$BL26 -> 16.5 | BO26: =+BO$18*$BL26 -> 18 | BP26: =+BP$18*$BL26 -> 19.5 | BQ26: =+BQ$18*$BL26 -> 21 | BR26: =+BR$18*$BL26 -> 22.5 | BS26: =+BS$18*$BL26 -> 24 | BT26: =+BT$18*$BL26 -> 25.5 | ... CB26: =+CB$18*$BL26 -> 42 | CD26: 1 | CF26: =+($CF$20*CD26)*$CF$18 -> 0.83333333 | CG26: =+($CG$20*CD26)*$CG$18 -> 1.6666667 | CH26: =+($CH$20*CD26)*$CH$18 -> 2.5 | CI26: =+($CI$20*CD26)*$CI$18 -> 3.3333333 | CJ26: =+($CJ$20*CD26)*$CJ$18 -> 4.1666667 | CK26: =+($CK$20*CD26)*$CK$18 -> 5 | CL26: =+($CL$20*CD26)*$CL$18 -> 5.8333333 | CM26: =+($CM$20*CD26)*$CM$18 -> 6.6666667 | CN26: =+($CN$20*CD26)*$CN$18 -> 7.5 | CO26: =+($CO$20*CD26)*$CO$18 -> 8.3333333 | CP26: =+($CP$20*CD26)*$CP$18 -> 9.1666667 | CQ26: =+($CQ$20*CD26)*$CQ$18 -> 10 | CR26: =+($CR$20*CD26)*$CR$18 -> 10.833333 | CS26: =+($CS$20*CD26)*$CS$18 -> 11.666667 | CT26: =+($CT$20*CD26)*$CT$18 -> 12.5 | CU26: =+($CU$20*CD26)*$CU$18 -> 13.333333
A27: 6 | B27: 1.1333333 | D27: 3.5 | E27: 1 | F27: =+$F$18*E27 -> 3.75 | H27: 7 | I27: 1 | J27: =+J$18*$H27/12*$I27 -> 2.625 | K27: =+K$18*$H27/12*$I27 -> 1.1666667 | L27: =+L$18*$H27/12*$I27 -> 2.625 | M27: =+M$18*$H27/12*$I27 -> 2.3333333 | N27: =+N$18*$H27/12*$I27 -> 2.9166667 | O27: =+O$18*$H27/12*$I27 -> 3.2083333 | P27: =+P$18*$H27/12*$I27 -> 2.1875 | Q27: =+Q$18*$H27/12*$I27 -> 2.4791667 | R27: =+R$18*$H27/12*$I27 -> 3.5 | T27: 7 | U27: 1 | V27: =+V$18*$H27/12*$I27 -> 3.28125 | W27: =+W$18*$H27/12*$I27 -> 1.75 | X27: =+X$18*$H27/12*$I27 -> 3.9375 | Y27: =+Y$18*$H27/12*$I27 -> 3.5 | Z27: =+Z$18*$H27/12*$I27 -> 8.75 | AA27: =+AA$18*$H27/12*$I27 -> 11.229167 | AB27: =+AB$18*$H27/12*$I27 -> 3.28125 | AC27: =+AC$18*$H27/12*$I27 -> 3.71875 | AD27: =+AD$18*$H27/12*$I27 -> 10.5 | AF27: 7 | AG27: 1 | AH27: =+AH$18*$AF27/12*$AG27 -> 4.1015625 | AI27: =+AI$18*$AF27/12*$AG27 -> 2.1875 | AJ27: =+AJ$18*$AF27/12*$AG27 -> 3.9375 | AK27: =+AK$18*$AF27/12*$AG27 -> 3.5 | AL27: =+AL$18*$AF27/12*$AG27 -> 13.125 | AM27: =+AM$18*$AF27/12*$AG27 -> 16.84375 | AN27: =+AN$18*$AF27/12*$AG27 -> 3.28125 | AO27: =+AO$18*$AF27/12*$AG27 -> 1.1666667 | ... AR27: =+AR$18*$AF27/12*$AG27 -> 15.75 | AT27: 1.25 | AU27: =+AU26+(AT27/AT26*AU26*$AU$18) -> 11.007257 | AW27: 1.25 | AX27: 1 | AY27: =+AY$18*$H27/12*$I27 -> 1.1666667 | AZ27: =+AZ$18*$H27/12*$I27 -> 1.75 | BA27: =+BA$18*$H27/12*$I27 -> 2.9166667 | BB27: =+BB$18*$H27/12*$I27 -> 3.5 | BC27: =+BC$18*$H27/12*$I27 -> 17.5 | BD27: =+BD$18*$H27/12*$I27 -> 23.333333 | BE27: =+BE$18*$H27/12*$I27 -> 11.666667 | BF27: =+BF$18*$H27/12*$I27 -> 4.0833333 | BG27: =+BG$18*$H27/12*$I27 -> 5.8333333 | BI27: 7 | BJ27: =+BJ26+(BI27/BI26*BJ26*$BJ$18) -> 13.221087 | BL27: =+BL26+0.5 -> 3.5 | BM27: =+BM$18*$BL27 -> 17.5 | BN27: =+BN$18*$BL27 -> 19.25 | BO27: =+BO$18*$BL27 -> 21 | BP27: =+BP$18*$BL27 -> 22.75 | BQ27: =+BQ$18*$BL27 -> 24.5 | BR27: =+BR$18*$BL27 -> 26.25 | BS27: =+BS$18*$BL27 -> 28 | BT27: =+BT$18*$BL27 -> 29.75 | ... CB27: =+CB$18*$BL27 -> 49 | CD27: 1.25 | CF27: =+($CF$20*CD27)*$CF$18 -> 1.0416667 | CG27: =+($CG$20*CD27)*$CG$18 -> 2.0833333 | CH27: =+($CH$20*CD27)*$CH$18 -> 3.125 | CI27: =+($CI$20*CD27)*$CI$18 -> 4.1666667 | CJ27: =+($CJ$20*CD27)*$CJ$18 -> 5.2083333 | CK27: =+($CK$20*CD27)*$CK$18 -> 6.25 | CL27: =+($CL$20*CD27)*$CL$18 -> 7.2916667 | CM27: =+($CM$20*CD27)*$CM$18 -> 8.3333333 | CN27: =+($CN$20*CD27)*$CN$18 -> 9.375 | CO27: =+($CO$20*CD27)*$CO$18 -> 10.416667 | CP27: =+($CP$20*CD27)*$CP$18 -> 11.458333 | CQ27: =+($CQ$20*CD27)*$CQ$18 -> 12.5 | CR27: =+($CR$20*CD27)*$CR$18 -> 13.541667 | CS27: =+($CS$20*CD27)*$CS$18 -> 14.583333 | CT27: =+($CT$20*CD27)*$CT$18 -> 15.625 | CU27: =+($CU$20*CD27)*$CU$18 -> 16.666667
